Workbook

Sheet Dashboard
B2: Customer Churn Dashboard
B3: Telecom subscription customers (IBM Telco sample, 7,043 customers). Use the two filters to explore any segment.
Z4: filter criteria (helper)
B5: Contract filter | C5: All | E5: Internet filter | F5: All | Z5: =IF(C5="All","*",C5) -> *
Z6: =IF(F5="All","*",F5) -> *
B7: =COUNTIFS(Data!$P$2:$P$7044,$Z$5,Data!$I$2:$I$7044,$Z$6) -> 7043 | D7: =IFERROR(COUNTIFS(Data!$P$2:$P$7044,$Z$5,Data!$I$2:$I$7044,$Z$6,Data!$W$2:$W$7044,1)/COUNTIFS(Data!$P$2:$P$7044,$Z$5,Data!$I$2:$I$7044,$Z$6),0) -> 0.26536987 | F7: =SUMIFS(Data!$AA$2:$AA$7044,Data!$P$2:$P$7044,$Z$5,Data!$I$2:$I$7044,$Z$6) -> 139130.85 | H7: =SUMIFS(Data!$AA$2:$AA$7044,Data!$P$2:$P$7044,$Z$5,Data!$I$2:$I$7044,$Z$6)*12 -> 1669570.2 | J7: =IFERROR(AVERAGEIFS(Data!$F$2:$F$7044,Data!$P$2:$P$7044,$Z$5,Data!$I$2:$I$7044,$Z$6,Data!$W$2:$W$7044,1),0) -> 17.979133
B8: Customers | D8: Churn rate | F8: Lost monthly revenue | H8: Annual revenue lost | J8: Avg tenure of churners (months)
B9: =IF(AND(C5="All",F5="All"),"Showing all customers","Showing: "&C5&" contracts, "&F5&" internet") -> Showing all customers
B12: Churn rate by tenure | I12: Churn rate by payment method
B13: Segment | C13: Customers | D13: Churn rate | I13: Segment | J13: Customers | K13: Churn rate
B14: 0-12 months | C14: =COUNTIFS(Data!$P$2:$P$7044,$Z$5,Data!$I$2:$I$7044,$Z$6,Data!$X$2:$X$7044,B14) -> 2186 | D14: =IFERROR(COUNTIFS(Data!$P$2:$P$7044,$Z$5,Data!$I$2:$I$7044,$Z$6,Data!$X$2:$X$7044,B14,Data!$W$2:$W$7044,1)/C14,0) -> 0.47438243 | I14: Electronic check | J14: =COUNTIFS(Data!$P$2:$P$7044,$Z$5,Data!$I$2:$I$7044,$Z$6,Data!$R$2:$R$7044,I14) -> 2365 | K14: =IFERROR(COUNTIFS(Data!$P$2:$P$7044,$Z$5,Data!$I$2:$I$7044,$Z$6,Data!$R$2:$R$7044,I14,Data!$W$2:$W$7044,1)/J14,0) -> 0.45285412
B15: 13-24 months | C15: =COUNTIFS(Data!$P$2:$P$7044,$Z$5,Data!$I$2:$I$7044,$Z$6,Data!$X$2:$X$7044,B15) -> 1024 | D15: =IFERROR(COUNTIFS(Data!$P$2:$P$7044,$Z$5,Data!$I$2:$I$7044,$Z$6,Data!$X$2:$X$7044,B15,Data!$W$2:$W$7044,1)/C15,0) -> 0.28710938 | I15: Mailed check | J15: =COUNTIFS(Data!$P$2:$P$7044,$Z$5,Data!$I$2:$I$7044,$Z$6,Data!$R$2:$R$7044,I15) -> 1612 | K15: =IFERROR(COUNTIFS(Data!$P$2:$P$7044,$Z$5,Data!$I$2:$I$7044,$Z$6,Data!$R$2:$R$7044,I15,Data!$W$2:$W$7044,1)/J15,0) -> 0.191067
B16: 25-48 months | C16: =COUNTIFS(Data!$P$2:$P$7044,$Z$5,Data!$I$2:$I$7044,$Z$6,Data!$X$2:$X$7044,B16) -> 1594 | D16: =IFERROR(COUNTIFS(Data!$P$2:$P$7044,$Z$5,Data!$I$2:$I$7044,$Z$6,Data!$X$2:$X$7044,B16,Data!$W$2:$W$7044,1)/C16,0) -> 0.20388959 | I16: Bank transfer (automatic) | J16: =COUNTIFS(Data!$P$2:$P$7044,$Z$5,Data!$I$2:$I$7044,$Z$6,Data!$R$2:$R$7044,I16) -> 1544 | K16: =IFERROR(COUNTIFS(Data!$P$2:$P$7044,$Z$5,Data!$I$2:$I$7044,$Z$6,Data!$R$2:$R$7044,I16,Data!$W$2:$W$7044,1)/J16,0) -> 0.16709845
B17: 49-72 months | C17: =COUNTIFS(Data!$P$2:$P$7044,$Z$5,Data!$I$2:$I$7044,$Z$6,Data!$X$2:$X$7044,B17) -> 2239 | D17: =IFERROR(COUNTIFS(Data!$P$2:$P$7044,$Z$5,Data!$I$2:$I$7044,$Z$6,Data!$X$2:$X$7044,B17,Data!$W$2:$W$7044,1)/C17,0) -> 0.095131755 | I17: Credit card (automatic) | J17: =COUNTIFS(Data!$P$2:$P$7044,$Z$5,Data!$I$2:$I$7044,$Z$6,Data!$R$2:$R$7044,I17) -> 1522 | K17: =IFERROR(COUNTIFS(Data!$P$2:$P$7044,$Z$5,Data!$I$2:$I$7044,$Z$6,Data!$R$2:$R$7044,I17,Data!$W$2:$W$7044,1)/J17,0) -> 0.15243101
B31: Churn rate by tech support | I31: Churn rate by contract
B32: Segment | C32: Customers | D32: Churn rate | I32: Segment | J32: Customers | K32: Churn rate
B33: No | C33: =COUNTIFS(Data!$P$2:$P$7044,$Z$5,Data!$I$2:$I$7044,$Z$6,Data!$M$2:$M$7044,B33) -> 3473 | D33: =IFERROR(COUNTIFS(Data!$P$2:$P$7044,$Z$5,Data!$I$2:$I$7044,$Z$6,Data!$M$2:$M$7044,B33,Data!$W$2:$W$7044,1)/C33,0) -> 0.41635474 | I33: Month-to-month | J33: =COUNTIFS(Data!$P$2:$P$7044,$Z$5,Data!$I$2:$I$7044,$Z$6,Data!$P$2:$P$7044,I33) -> 3875 | K33: =IFERROR(COUNTIFS(Data!$P$2:$P$7044,$Z$5,Data!$I$2:$I$7044,$Z$6,Data!$P$2:$P$7044,I33,Data!$W$2:$W$7044,1)/J33,0) -> 0.42709677
B34: Yes | C34: =COUNTIFS(Data!$P$2:$P$7044,$Z$5,Data!$I$2:$I$7044,$Z$6,Data!$M$2:$M$7044,B34) -> 2044 | D34: =IFERROR(COUNTIFS(Data!$P$2:$P$7044,$Z$5,Data!$I$2:$I$7044,$Z$6,Data!$M$2:$M$7044,B34,Data!$W$2:$W$7044,1)/C34,0) -> 0.15166341 | I34: One year | J34: =COUNTIFS(Data!$P$2:$P$7044,$Z$5,Data!$I$2:$I$7044,$Z$6,Data!$P$2:$P$7044,I34) -> 1473 | K34: =IFERROR(COUNTIFS(Data!$P$2:$P$7044,$Z$5,Data!$I$2:$I$7044,$Z$6,Data!$P$2:$P$7044,I34,Data!$W$2:$W$7044,1)/J34,0) -> 0.11269518
B35: No internet service | C35: =COUNTIFS(Data!$P$2:$P$7044,$Z$5,Data!$I$2:$I$7044,$Z$6,Data!$M$2:$M$7044,B35) -> 1526 | D35: =IFERROR(COUNTIFS(Data!$P$2:$P$7044,$Z$5,Data!$I$2:$I$7044,$Z$6,Data!$M$2:$M$7044,B35,Data!$W$2:$W$7044,1)/C35,0) -> 0.074049803 | I35: Two year | J35: =COUNTIFS(Data!$P$2:$P$7044,$Z$5,Data!$I$2:$I$7044,$Z$6,Data!$P$2:$P$7044,I35) -> 1695 | K35: =IFERROR(COUNTIFS(Data!$P$2:$P$7044,$Z$5,Data!$I$2:$I$7044,$Z$6,Data!$P$2:$P$7044,I35,Data!$W$2:$W$7044,1)/J35,0) -> 0.028318584
B50: Key findings
B51: 1. Month-to-month customers churn at 42.7%, vs 11.3% on 1-year and 2.8% on 2-year contracts. They make up 87% of lost revenue.
B52: 2. Risk is front-loaded: 47.4% of customers in their first year leave, vs 9.5% after 4+ years.
B53: 3. Electronic-check payers churn at 45.3%, roughly 3x the rate of automatic payers.
B54: 4. Customers without tech support or online security churn at about 42%, vs about 15% with them.
B55: 5. 533 active high-risk customers ($41.8K monthly revenue) are the retention target; see Retention_Scenario.

Sheet README
B2: Customer Churn and Revenue-at-Risk Analysis
B3: Author: Pratiti Toppo | Tools: Excel (formulas, pivots-style analysis, charts, data validation, CHITEST, NORMSINV), SQL
B5: Business question
B6: A subscription telecom company is losing about 1 in 4 customers. Who is leaving, why, how much revenue is at risk, and what should we do?
B8: How to use this workbook
B9: Dashboard: KPIs and charts. Change the yellow filter cells (contract, internet) to explore any segment.
B10: Analysis: churn rate, revenue and lift for 10 customer dimensions.
B11: Stats_Tests: chi-square test for each driver, to check the patterns are not chance.
B12: Risk_Segments: the riskiest combinations of contract, internet and payment method.
B13: At_Risk: a simple 0-6 risk score, proof that it works, and the active customers it flags.
B14: Retention_Scenario: what-if model for a contract-upgrade discount, with a sensitivity table.
B15: Test_Design: sample size for a pilot test of the offer.
... B35: Churn = customers who left within the last month of the snapshot.

Sheet Data
A1: customerID | B1: gender | C1: SeniorCitizen | D1: Partner | E1: Dependents | F1: tenure | G1: PhoneService | H1: MultipleLines | I1: InternetService | J1: OnlineSecurity | K1: OnlineBackup | L1: DeviceProtection | M1: TechSupport | N1: StreamingTV | O1: StreamingMovies | P1: Contract | Q1: PaperlessBilling | R1: PaymentMethod | S1: MonthlyCharges | T1: TotalCharges | U1: Churn | V1: TotalCharges_Clean | W1: Churn_Flag | X1: Tenure_Band | Y1: Senior | Z1: Addon_Count | AA1: Lost_MRR | AB1: Risk_Score | AC1: Risk_Level
A2: 7590-VHVEG | B2: Female | C2: 0 | D2: Yes | E2: No | F2: 1 | G2: No | H2: No phone service | I2: DSL | J2: No | K2: Yes | L2: No | M2: No | N2: No | O2: No | P2: Month-to-month | Q2: Yes | R2: Electronic check | S2: 29.85 | T2: 29.85 | U2: No | V2: =IF(ISNUMBER(T2),T2,0) -> 29.85 | W2: =IF(U2="Yes",1,0) -> 0 | X2: =IF(F2<=12,"0-12 months",IF(F2<=24,"13-24 months",IF(F2<=48,"25-48 months","49-72 months"))) -> 0-12 months | Y2: =IF(C2=1,"Yes","No") -> No | Z2: =COUNTIF(J2:O2,"Yes") -> 1 | AA2: =S2*W2 -> 0 | AB2: =(P2="Month-to-month")+(I2="Fiber optic")+(R2="Electronic check")+(F2<=12)+(M2="No")+(J2="No") -> 5 | AC2: =IF(AB2>=5,"High",IF(AB2>=3,"Medium","Low")) -> High
A3: 5575-GNVDE | B3: Male | C3: 0 | D3: No | E3: No | F3: 34 | G3: Yes | H3: No | I3: DSL | J3: Yes | K3: No | L3: Yes | M3: No | N3: No | O3: No | P3: One year | Q3: No | R3: Mailed check | S3: 56.95 | T3: 1889.5 | U3: No | V3: =IF(ISNUMBER(T3),T3,0) -> 1889.5 | W3: =IF(U3="Yes",1,0) -> 0 | X3: =IF(F3<=12,"0-12 months",IF(F3<=24,"13-24 months",IF(F3<=48,"25-48 months","49-72 months"))) -> 25-48 months | Y3: =IF(C3=1,"Yes","No") -> No | Z3: =COUNTIF(J3:O3,"Yes") -> 2 | AA3: =S3*W3 -> 0 | AB3: =(P3="Month-to-month")+(I3="Fiber optic")+(R3="Electronic check")+(F3<=12)+(M3="No")+(J3="No") -> 1 | AC3: =IF(AB3>=5,"High",IF(AB3>=3,"Medium","Low")) -> Low
A4: 3668-QPYBK | B4: Male | C4: 0 | D4: No | E4: No | F4: 2 | G4: Yes | H4: No | I4: DSL | J4: Yes | K4: Yes | L4: No | M4: No | N4: No | O4: No | P4: Month-to-month | Q4: Yes | R4: Mailed check | S4: 53.85 | T4: 108.15 | U4: Yes | V4: =IF(ISNUMBER(T4),T4,0) -> 108.15 | W4: =IF(U4="Yes",1,0) -> 1 | X4: =IF(F4<=12,"0-12 months",IF(F4<=24,"13-24 months",IF(F4<=48,"25-48 months","49-72 months"))) -> 0-12 months | Y4: =IF(C4=1,"Yes","No") -> No | Z4: =COUNTIF(J4:O4,"Yes") -> 2 | AA4: =S4*W4 -> 53.85 | AB4: =(P4="Month-to-month")+(I4="Fiber optic")+(R4="Electronic check")+(F4<=12)+(M4="No")+(J4="No") -> 3 | AC4: =IF(AB4>=5,"High",IF(AB4>=3,"Medium","Low")) -> Medium
A5: 7795-CFOCW | B5: Male | C5: 0 | D5: No | E5: No | F5: 45 | G5: No | H5: No phone service | I5: DSL | J5: Yes | K5: No | L5: Yes | M5: Yes | N5: No | O5: No | P5: One year | Q5: No | R5: Bank transfer (automatic) | S5: 42.3 | T5: 1840.75 | U5: No | V5: =IF(ISNUMBER(T5),T5,0) -> 1840.75 | W5: =IF(U5="Yes",1,0) -> 0 | X5: =IF(F5<=12,"0-12 months",IF(F5<=24,"13-24 months",IF(F5<=48,"25-48 months","49-72 months"))) -> 25-48 months | Y5: =IF(C5=1,"Yes","No") -> No | Z5: =COUNTIF(J5:O5,"Yes") -> 3 | AA5: =S5*W5 -> 0 | AB5: =(P5="Month-to-month")+(I5="Fiber optic")+(R5="Electronic check")+(F5<=12)+(M5="No")+(J5="No") -> 0 | AC5: =IF(AB5>=5,"High",IF(AB5>=3,"Medium","Low")) -> Low
A6: 9237-HQITU | B6: Female | C6: 0 | D6: No | E6: No | F6: 2 | G6: Yes | H6: No | I6: Fiber optic | J6: No | K6: No | L6: No | M6: No | N6: No | O6: No | P6: Month-to-month | Q6: Yes | R6: Electronic check | S6: 70.7 | T6: 151.65 | U6: Yes | V6: =IF(ISNUMBER(T6),T6,0) -> 151.65 | W6: =IF(U6="Yes",1,0) -> 1 | X6: =IF(F6<=12,"0-12 months",IF(F6<=24,"13-24 months",IF(F6<=48,"25-48 months","49-72 months"))) -> 0-12 months | Y6: =IF(C6=1,"Yes","No") -> No | Z6: =COUNTIF(J6:O6,"Yes") -> 0 | AA6: =S6*W6 -> 70.7 | AB6: =(P6="Month-to-month")+(I6="Fiber optic")+(R6="Electronic check")+(F6<=12)+(M6="No")+(J6="No") -> 6 | AC6: =IF(AB6>=5,"High",IF(AB6>=3,"Medium","Low")) -> High
A7: 9305-CDSKC | B7: Female | C7: 0 | D7: No | E7: No | F7: 8 | G7: Yes | H7: Yes | I7: Fiber optic | J7: No | K7: No | L7: Yes | M7: No | N7: Yes | O7: Yes | P7: Month-to-month | Q7: Yes | R7: Electronic check | S7: 99.65 | T7: 820.5 | U7: Yes | V7: =IF(ISNUMBER(T7),T7,0) -> 820.5 | W7: =IF(U7="Yes",1,0) -> 1 | X7: =IF(F7<=12,"0-12 months",IF(F7<=24,"13-24 months",IF(F7<=48,"25-48 months","49-72 months"))) -> 0-12 months | Y7: =IF(C7=1,"Yes","No") -> No | Z7: =COUNTIF(J7:O7,"Yes") -> 3 | AA7: =S7*W7 -> 99.65 | AB7: =(P7="Month-to-month")+(I7="Fiber optic")+(R7="Electronic check")+(F7<=12)+(M7="No")+(J7="No") -> 6 | AC7: =IF(AB7>=5,"High",IF(AB7>=3,"Medium","Low")) -> High
A8: 1452-KIOVK | B8: Male | C8: 0 | D8: No | E8: Yes | F8: 22 | G8: Yes | H8: Yes | I8: Fiber optic | J8: No | K8: Yes | L8: No | M8: No | N8: Yes | O8: No | P8: Month-to-month | Q8: Yes | R8: Credit card (automatic) | S8: 89.1 | T8: 1949.4 | U8: No | V8: =IF(ISNUMBER(T8),T8,0) -> 1949.4 | W8: =IF(U8="Yes",1,0) -> 0 | X8: =IF(F8<=12,"0-12 months",IF(F8<=24,"13-24 months",IF(F8<=48,"25-48 months","49-72 months"))) -> 13-24 months | Y8: =IF(C8=1,"Yes","No") -> No | Z8: =COUNTIF(J8:O8,"Yes") -> 2 | AA8: =S8*W8 -> 0 | AB8: =(P8="Month-to-month")+(I8="Fiber optic")+(R8="Electronic check")+(F8<=12)+(M8="No")+(J8="No") -> 4 | AC8: =IF(AB8>=5,"High",IF(AB8>=3,"Medium","Low")) -> Medium
A9: 6713-OKOMC | B9: Female | C9: 0 | D9: No | E9: No | F9: 10 | G9: No | H9: No phone service | I9: DSL | J9: Yes | K9: No | L9: No | M9: No | N9: No | O9: No | P9: Month-to-month | Q9: No | R9: Mailed check | S9: 29.75 | T9: 301.9 | U9: No | V9: =IF(ISNUMBER(T9),T9,0) -> 301.9 | W9: =IF(U9="Yes",1,0) -> 0 | X9: =IF(F9<=12,"0-12 months",IF(F9<=24,"13-24 months",IF(F9<=48,"25-48 months","49-72 months"))) -> 0-12 months | Y9: =IF(C9=1,"Yes","No") -> No | Z9: =COUNTIF(J9:O9,"Yes") -> 1 | AA9: =S9*W9 -> 0 | AB9: =(P9="Month-to-month")+(I9="Fiber optic")+(R9="Electronic check")+(F9<=12)+(M9="No")+(J9="No") -> 3 | AC9: =IF(AB9>=5,"High",IF(AB9>=3,"Medium","Low")) -> Medium
A10: 7892-POOKP | B10: Female | C10: 0 | D10: Yes | E10: No | F10: 28 | G10: Yes | H10: Yes | I10: Fiber optic | J10: No | K10: No | L10: Yes | M10: Yes | N10: Yes | O10: Yes | P10: Month-to-month | Q10: Yes | R10: Electronic check | S10: 104.8 | T10: 3046.05 | U10: Yes | V10: =IF(ISNUMBER(T10),T10,0) -> 3046.05 | W10: =IF(U10="Yes",1,0) -> 1 | X10: =IF(F10<=12,"0-12 months",IF(F10<=24,"13-24 months",IF(F10<=48,"25-48 months","49-72 months"))) -> 25-48 months | Y10: =IF(C10=1,"Yes","No") -> No | Z10: =COUNTIF(J10:O10,"Yes") -> 4 | AA10: =S10*W10 -> 104.8 | AB10: =(P10="Month-to-month")+(I10="Fiber optic")+(R10="Electronic check")+(F10<=12)+(M10="No")+(J10="No") -> 4 | AC10: =IF(AB10>=5,"High",IF(AB10>=3,"Medium","Low")) -> Medium
A11: 6388-TABGU | B11: Male | C11: 0 | D11: No | E11: Yes | F11: 62 | G11: Yes | H11: No | I11: DSL | J11: Yes | K11: Yes | L11: No | M11: No | N11: No | O11: No | P11: One year | Q11: No | R11: Bank transfer (automatic) | S11: 56.15 | T11: 3487.95 | U11: No | V11: =IF(ISNUMBER(T11),T11,0) -> 3487.95 | W11: =IF(U11="Yes",1,0) -> 0 | X11: =IF(F11<=12,"0-12 months",IF(F11<=24,"13-24 months",IF(F11<=48,"25-48 months","49-72 months"))) -> 49-72 months | Y11: =IF(C11=1,"Yes","No") -> No | Z11: =COUNTIF(J11:O11,"Yes") -> 2 | AA11: =S11*W11 -> 0 | AB11: =(P11="Month-to-month")+(I11="Fiber optic")+(R11="Electronic check")+(F11<=12)+(M11="No")+(J11="No") -> 1 | AC11: =IF(AB11>=5,"High",IF(AB11>=3,"Medium","Low")) -> Low
A12: 9763-GRSKD | B12: Male | C12: 0 | D12: Yes | E12: Yes | F12: 13 | G12: Yes | H12: No | I12: DSL | J12: Yes | K12: No | L12: No | M12: No | N12: No | O12: No | P12: Month-to-month | Q12: Yes | R12: Mailed check | S12: 49.95 | T12: 587.45 | U12: No | V12: =IF(ISNUMBER(T12),T12,0) -> 587.45 | W12: =IF(U12="Yes",1,0) -> 0 | X12: =IF(F12<=12,"0-12 months",IF(F12<=24,"13-24 months",IF(F12<=48,"25-48 months","49-72 months"))) -> 13-24 months | Y12: =IF(C12=1,"Yes","No") -> No | Z12: =COUNTIF(J12:O12,"Yes") -> 1 | AA12: =S12*W12 -> 0 | AB12: =(P12="Month-to-month")+(I12="Fiber optic")+(R12="Electronic check")+(F12<=12)+(M12="No")+(J12="No") -> 2 | AC12: =IF(AB12>=5,"High",IF(AB12>=3,"Medium","Low")) -> Low
A13: 7469-LKBCI | B13: Male | C13: 0 | D13: No | E13: No | F13: 16 | G13: Yes | H13: No | I13: No | J13: No internet service | K13: No internet service | L13: No internet service | M13: No internet service | N13: No internet service | O13: No internet service | P13: Two year | Q13: No | R13: Credit card (automatic) | S13: 18.95 | T13: 326.8 | U13: No | V13: =IF(ISNUMBER(T13),T13,0) -> 326.8 | W13: =IF(U13="Yes",1,0) -> 0 | X13: =IF(F13<=12,"0-12 months",IF(F13<=24,"13-24 months",IF(F13<=48,"25-48 months","49-72 months"))) -> 13-24 months | Y13: =IF(C13=1,"Yes","No") -> No | Z13: =COUNTIF(J13:O13,"Yes") -> 0 | AA13: =S13*W13 -> 0 | AB13: =(P13="Month-to-month")+(I13="Fiber optic")+(R13="Electronic check")+(F13<=12)+(M13="No")+(J13="No") -> 0 | AC13: =IF(AB13>=5,"High",IF(AB13>=3,"Medium","Low")) -> Low
... A489: 3649-JPUGY | B489: Male | C489: 0 | D489: No | E489: No | F489: 72 | G489: Yes | H489: Yes | I489: DSL | J489: No | K489: Yes | L489: Yes | M489: Yes | N489: Yes | O489: Yes | P489: Two year | Q489: Yes | R489: Bank transfer (automatic) | S489: 88.6 | T489: 6201.95 | U489: No | V489: =IF(ISNUMBER(T489),T489,0) -> 6201.95 | W489: =IF(U489="Yes",1,0) -> 0 | X489: =IF(F489<=12,"0-12 months",IF(F489<=24,"13-24 months",IF(F489<=48,"25-48 months","49-72 months"))) -> 49-72 months | Y489: =IF(C489=1,"Yes","No") -> No | Z489: =COUNTIF(J489:O489,"Yes") -> 5 | AA489: =S489*W489 -> 0 | AB489: =(P489="Month-to-month")+(I489="Fiber optic")+(R489="Electronic check")+(F489<=12)+(M489="No")+(J489="No") -> 1 | AC489: =IF(AB489>=5,"High",IF(AB489>=3,"Medium","Low")) -> Low
A490: 4472-LVYGI | B490: Female | C490: 0 | D490: Yes | E490: Yes | F490: 0 | G490: No | H490: No phone service | I490: DSL | J490: Yes | K490: No | L490: Yes | M490: Yes | N490: Yes | O490: No | P490: Two year | Q490: Yes | R490: Bank transfer (automatic) | S490: 52.55 | U490: No | V490: =IF(ISNUMBER(T490),T490,0) -> 0 | W490: =IF(U490="Yes",1,0) -> 0 | X490: =IF(F490<=12,"0-12 months",IF(F490<=24,"13-24 months",IF(F490<=48,"25-48 months","49-72 months"))) -> 0-12 months | Y490: =IF(C490=1,"Yes","No") -> No | Z490: =COUNTIF(J490:O490,"Yes") -> 4 | AA490: =S490*W490 -> 0 | AB490: =(P490="Month-to-month")+(I490="Fiber optic")+(R490="Electronic check")+(F490<=12)+(M490="No")+(J490="No") -> 1 | AC490: =IF(AB490>=5,"High",IF(AB490>=3,"Medium","Low")) -> Low
A491: 8372-JUXUI | B491: Male | C491: 0 | D491: No | E491: Yes | F491: 1 | G491: Yes | H491: Yes | I491: Fiber optic | J491: No | K491: No | L491: No | M491: No | N491: No | O491: No | P491: Month-to-month | Q491: Yes | R491: Electronic check | S491: 74.35 | T491: 74.35 | U491: Yes | V491: =IF(ISNUMBER(T491),T491,0) -> 74.35 | W491: =IF(U491="Yes",1,0) -> 1 | X491: =IF(F491<=12,"0-12 months",IF(F491<=24,"13-24 months",IF(F491<=48,"25-48 months","49-72 months"))) -> 0-12 months | Y491: =IF(C491=1,"Yes","No") -> No | Z491: =COUNTIF(J491:O491,"Yes") -> 0 | AA491: =S491*W491 -> 74.35 | AB491: =(P491="Month-to-month")+(I491="Fiber optic")+(R491="Electronic check")+(F491<=12)+(M491="No")+(J491="No") -> 6 | AC491: =IF(AB491>=5,"High",IF(AB491>=3,"Medium","Low")) -> High
A492: 3552-CTCYF | B492: Male | C492: 0 | D492: Yes | E492: Yes | F492: 63 | G492: Yes | H492: Yes | I492: Fiber optic | J492: No | K492: Yes | L492: Yes | M492: No | N492: Yes | O492: Yes | P492: Two year | Q492: Yes | R492: Bank transfer (automatic) | S492: 104.8 | T492: 6597.25 | U492: No | V492: =IF(ISNUMBER(T492),T492,0) -> 6597.25 | W492: =IF(U492="Yes",1,0) -> 0 | X492: =IF(F492<=12,"0-12 months",IF(F492<=24,"13-24 months",IF(F492<=48,"25-48 months","49-72 months"))) -> 49-72 months | Y492: =IF(C492=1,"Yes","No") -> No | Z492: =COUNTIF(J492:O492,"Yes") -> 4 | AA492: =S492*W492 -> 0 | AB492: =(P492="Month-to-month")+(I492="Fiber optic")+(R492="Electronic check")+(F492<=12)+(M492="No")+(J492="No") -> 3 | AC492: =IF(AB492>=5,"High",IF(AB492>=3,"Medium","Low")) -> Medium
A493: 6778-YSNIH | B493: Female | C493: 0 | D493: No | E493: No | F493: 2 | G493: Yes | H493: No | I493: DSL | J493: No | K493: Yes | L493: No | M493: No | N493: Yes | O493: No | P493: Month-to-month | Q493: Yes | R493: Electronic check | S493: 59 | T493: 114.15 | U493: No | V493: =IF(ISNUMBER(T493),T493,0) -> 114.15 | W493: =IF(U493="Yes",1,0) -> 0 | X493: =IF(F493<=12,"0-12 months",IF(F493<=24,"13-24 months",IF(F493<=48,"25-48 months","49-72 months"))) -> 0-12 months | Y493: =IF(C493=1,"Yes","No") -> No | Z493: =COUNTIF(J493:O493,"Yes") -> 2 | AA493: =S493*W493 -> 0 | AB493: =(P493="Month-to-month")+(I493="Fiber optic")+(R493="Electronic check")+(F493<=12)+(M493="No")+(J493="No") -> 5 | AC493: =IF(AB493>=5,"High",IF(AB493>=3,"Medium","Low")) -> High
A494: 0388-EOPEX | B494: Female | C494: 0 | D494: Yes | E494: No | F494: 2 | G494: Yes | H494: No | I494: Fiber optic | J494: Yes | K494: No | L494: No | M494: No | N494: No | O494: No | P494: Month-to-month | Q494: Yes | R494: Electronic check | S494: 74.4 | T494: 139.4 | U494: Yes | V494: =IF(ISNUMBER(T494),T494,0) -> 139.4 | W494: =IF(U494="Yes",1,0) -> 1 | X494: =IF(F494<=12,"0-12 months",IF(F494<=24,"13-24 months",IF(F494<=48,"25-48 months","49-72 months"))) -> 0-12 months | Y494: =IF(C494=1,"Yes","No") -> No | Z494: =COUNTIF(J494:O494,"Yes") -> 1 | AA494: =S494*W494 -> 74.4 | AB494: =(P494="Month-to-month")+(I494="Fiber optic")+(R494="Electronic check")+(F494<=12)+(M494="No")+(J494="No") -> 5 | AC494: =IF(AB494>=5,"High",IF(AB494>=3,"Medium","Low")) -> High
A495: 5756-OZRIO | B495: Male | C495: 1 | D495: Yes | E495: No | F495: 61 | G495: Yes | H495: Yes | I495: DSL | J495: No | K495: Yes | L495: No | M495: No | N495: No | O495: Yes | P495: One year | Q495: No | R495: Bank transfer (automatic) | S495: 64.05 | T495: 3902.6 | U495: No | V495: =IF(ISNUMBER(T495),T495,0) -> 3902.6 | W495: =IF(U495="Yes",1,0) -> 0 | X495: =IF(F495<=12,"0-12 months",IF(F495<=24,"13-24 months",IF(F495<=48,"25-48 months","49-72 months"))) -> 49-72 months | Y495: =IF(C495=1,"Yes","No") -> Yes | Z495: =COUNTIF(J495:O495,"Yes") -> 2 | AA495: =S495*W495 -> 0 | AB495: =(P495="Month-to-month")+(I495="Fiber optic")+(R495="Electronic check")+(F495<=12)+(M495="No")+(J495="No") -> 2 | AC495: =IF(AB495>=5,"High",IF(AB495>=3,"Medium","Low")) -> Low
A496: 6579-JPICP | B496: Male | C496: 0 | D496: No | E496: No | F496: 1 | G496: Yes | H496: No | I496: No | J496: No internet service | K496: No internet service | L496: No internet service | M496: No internet service | N496: No internet service | O496: No internet service | P496: Month-to-month | Q496: No | R496: Mailed check | S496: 20.4 | T496: 20.4 | U496: No | V496: =IF(ISNUMBER(T496),T496,0) -> 20.4 | W496: =IF(U496="Yes",1,0) -> 0 | X496: =IF(F496<=12,"0-12 months",IF(F496<=24,"13-24 months",IF(F496<=48,"25-48 months","49-72 months"))) -> 0-12 months | Y496: =IF(C496=1,"Yes","No") -> No | Z496: =COUNTIF(J496:O496,"Yes") -> 0 | AA496: =S496*W496 -> 0 | AB496: =(P496="Month-to-month")+(I496="Fiber optic")+(R496="Electronic check")+(F496<=12)+(M496="No")+(J496="No") -> 2 | AC496: =IF(AB496>=5,"High",IF(AB496>=3,"Medium","Low")) -> Low
A497: 8205-OTCHB | B497: Male | C497: 0 | D497: No | E497: No | F497: 22 | G497: No | H497: No phone service | I497: DSL | J497: No | K497: Yes | L497: Yes | M497: No | N497: No | O497: Yes | P497: One year | Q497: Yes | R497: Bank transfer (automatic) | S497: 43.75 | T497: 903.6 | U497: Yes | V497: =IF(ISNUMBER(T497),T497,0) -> 903.6 | W497: =IF(U497="Yes",1,0) -> 1 | X497: =IF(F497<=12,"0-12 months",IF(F497<=24,"13-24 months",IF(F497<=48,"25-48 months","49-72 months"))) -> 13-24 months | Y497: =IF(C497=1,"Yes","No") -> No | Z497: =COUNTIF(J497:O497,"Yes") -> 3 | AA497: =S497*W497 -> 43.75 | AB497: =(P497="Month-to-month")+(I497="Fiber optic")+(R497="Electronic check")+(F497<=12)+(M497="No")+(J497="No") -> 2 | AC497: =IF(AB497>=5,"High",IF(AB497>=3,"Medium","Low")) -> Low
A498: 4134-BSXLX | B498: Male | C498: 0 | D498: Yes | E498: No | F498: 28 | G498: Yes | H498: No | I498: DSL | J498: Yes | K498: Yes | L498: No | M498: Yes | N498: No | O498: No | P498: Month-to-month | Q498: No | R498: Mailed check | S498: 60.9 | T498: 1785.65 | U498: No | V498: =IF(ISNUMBER(T498),T498,0) -> 1785.65 | W498: =IF(U498="Yes",1,0) -> 0 | X498: =IF(F498<=12,"0-12 months",IF(F498<=24,"13-24 months",IF(F498<=48,"25-48 months","49-72 months"))) -> 25-48 months | Y498: =IF(C498=1,"Yes","No") -> No | Z498: =COUNTIF(J498:O498,"Yes") -> 3 | AA498: =S498*W498 -> 0 | AB498: =(P498="Month-to-month")+(I498="Fiber optic")+(R498="Electronic check")+(F498<=12)+(M498="No")+(J498="No") -> 1 | AC498: =IF(AB498>=5,"High",IF(AB498>=3,"Medium","Low")) -> Low
A499: 0505-SPOOW | B499: Female | C499: 0 | D499: Yes | E499: No | F499: 70 | G499: Yes | H499: No | I499: No | J499: No internet service | K499: No internet service | L499: No internet service | M499: No internet service | N499: No internet service | O499: No internet service | P499: Two year | Q499: No | R499: Bank transfer (automatic) | S499: 19.8 | T499: 1397.65 | U499: No | V499: =IF(ISNUMBER(T499),T499,0) -> 1397.65 | W499: =IF(U499="Yes",1,0) -> 0 | X499: =IF(F499<=12,"0-12 months",IF(F499<=24,"13-24 months",IF(F499<=48,"25-48 months","49-72 months"))) -> 49-72 months | Y499: =IF(C499=1,"Yes","No") -> No | Z499: =COUNTIF(J499:O499,"Yes") -> 0 | AA499: =S499*W499 -> 0 | AB499: =(P499="Month-to-month")+(I499="Fiber optic")+(R499="Electronic check")+(F499<=12)+(M499="No")+(J499="No") -> 0 | AC499: =IF(AB499>=5,"High",IF(AB499>=3,"Medium","Low")) -> Low
A500: 6235-VDHOM | B500: Female | C500: 1 | D500: No | E500: No | F500: 5 | G500: No | H500: No phone service | I500: DSL | J500: No | K500: Yes | L500: No | M500: No | N500: No | O500: No | P500: Month-to-month | Q500: No | R500: Electronic check | S500: 28.45 | T500: 131.05 | U500: Yes | V500: =IF(ISNUMBER(T500),T500,0) -> 131.05 | W500: =IF(U500="Yes",1,0) -> 1 | X500: =IF(F500<=12,"0-12 months",IF(F500<=24,"13-24 months",IF(F500<=48,"25-48 months","49-72 months"))) -> 0-12 months | Y500: =IF(C500=1,"Yes","No") -> Yes | Z500: =COUNTIF(J500:O500,"Yes") -> 1 | AA500: =S500*W500 -> 28.45 | AB500: =(P500="Month-to-month")+(I500="Fiber optic")+(R500="Electronic check")+(F500<=12)+(M500="No")+(J500="No") -> 5 | AC500: =IF(AB500>=5,"High",IF(AB500>=3,"Medium","Low")) -> High
A501: 7783-YKGDV | B501: Female | C501: 0 | D501: No | E501: No | F501: 12 | G501: Yes | H501: Yes | I501: Fiber optic | J501: Yes | K501: Yes | L501: Yes | M501: No | N501: No | O501: Yes | P501: Month-to-month | Q501: Yes | R501: Bank transfer (automatic) | S501: 99.7 | T501: 1238.45 | U501: Yes | V501: =IF(ISNUMBER(T501),T501,0) -> 1238.45 | W501: =IF(U501="Yes",1,0) -> 1 | X501: =IF(F501<=12,"0-12 months",IF(F501<=24,"13-24 months",IF(F501<=48,"25-48 months","49-72 months"))) -> 0-12 months | Y501: =IF(C501=1,"Yes","No") -> No | Z501: =COUNTIF(J501:O501,"Yes") -> 4 | AA501: =S501*W501 -> 99.7 | AB501: =(P501="Month-to-month")+(I501="Fiber optic")+(R501="Electronic check")+(F501<=12)+(M501="No")+(J501="No") -> 4 | AC501: =IF(AB501>=5,"High",IF(AB501>=3,"Medium","Low")) -> Medium
A502: 4374-YMUSQ | B502: Male | C502: 0 | D502: No | E502: No | F502: 34 | G502: Yes | H502: Yes | I502: Fiber optic | J502: Yes | K502: Yes | L502: Yes | M502: Yes | N502: Yes | O502: Yes | P502: One year | Q502: No | R502: Credit card (automatic) | S502: 116.25 | T502: 3899.05 | U502: No | V502: =IF(ISNUMBER(T502),T502,0) -> 3899.05 | W502: =IF(U502="Yes",1,0) -> 0 | X502: =IF(F502<=12,"0-12 months",IF(F502<=24,"13-24 months",IF(F502<=48,"25-48 months","49-72 months"))) -> 25-48 months | Y502: =IF(C502=1,"Yes","No") -> No | Z502: =COUNTIF(J502:O502,"Yes") -> 6 | AA502: =S502*W502 -> 0 | AB502: =(P502="Month-to-month")+(I502="Fiber optic")+(R502="Electronic check")+(F502<=12)+(M502="No")+(J502="No") -> 1 | AC502: =IF(AB502>=5,"High",IF(AB502>=3,"Medium","Low")) -> Low
... A754: 1410-RSCMR | B754: Male | C754: 0 | D754: Yes | E754: Yes | F754: 7 | G754: Yes | H754: No | I754: DSL | J754: Yes | K754: No | L754: Yes | M754: Yes | N754: No | O754: Yes | P754: Month-to-month | Q754: Yes | R754: Credit card (automatic) | S754: 71.35 | T754: 515.75 | U754: No | V754: =IF(ISNUMBER(T754),T754,0) -> 515.75 | W754: =IF(U754="Yes",1,0) -> 0 | X754: =IF(F754<=12,"0-12 months",IF(F754<=24,"13-24 months",IF(F754<=48,"25-48 months","49-72 months"))) -> 0-12 months | Y754: =IF(C754=1,"Yes","No") -> No | Z754: =COUNTIF(J754:O754,"Yes") -> 4 | AA754: =S754*W754 -> 0 | AB754: =(P754="Month-to-month")+(I754="Fiber optic")+(R754="Electronic check")+(F754<=12)+(M754="No")+(J754="No") -> 2 | AC754: =IF(AB754>=5,"High",IF(AB754>=3,"Medium","Low")) -> Low
A755: 3115-CZMZD | B755: Male | C755: 0 | D755: No | E755: Yes | F755: 0 | G755: Yes | H755: No | I755: No | J755: No internet service | K755: No internet service | L755: No internet service | M755: No internet service | N755: No internet service | O755: No internet service | P755: Two year | Q755: No | R755: Mailed check | S755: 20.25 | U755: No | V755: =IF(ISNUMBER(T755),T755,0) -> 0 | W755: =IF(U755="Yes",1,0) -> 0 | X755: =IF(F755<=12,"0-12 months",IF(F755<=24,"13-24 months",IF(F755<=48,"25-48 months","49-72 months"))) -> 0-12 months | Y755: =IF(C755=1,"Yes","No") -> No | Z755: =COUNTIF(J755:O755,"Yes") -> 0 | AA755: =S755*W755 -> 0 | AB755: =(P755="Month-to-month")+(I755="Fiber optic")+(R755="Electronic check")+(F755<=12)+(M755="No")+(J755="No") -> 1 | AC755: =IF(AB755>=5,"High",IF(AB755>=3,"Medium","Low")) -> Low
A756: 0139-IVFJG | B756: Female | C756: 0 | D756: Yes | E756: No | F756: 2 | G756: Yes | H756: No | I756: Fiber optic | J756: Yes | K756: Yes | L756: No | M756: No | N756: Yes | O756: No | P756: Month-to-month | Q756: No | R756: Electronic check | S756: 90.35 | T756: 190.5 | U756: No | V756: =IF(ISNUMBER(T756),T756,0) -> 190.5 | W756: =IF(U756="Yes",1,0) -> 0 | X756: =IF(F756<=12,"0-12 months",IF(F756<=24,"13-24 months",IF(F756<=48,"25-48 months","49-72 months"))) -> 0-12 months | Y756: =IF(C756=1,"Yes","No") -> No | Z756: =COUNTIF(J756:O756,"Yes") -> 3 | AA756: =S756*W756 -> 0 | AB756: =(P756="Month-to-month")+(I756="Fiber optic")+(R756="Electronic check")+(F756<=12)+(M756="No")+(J756="No") -> 5 | AC756: =IF(AB756>=5,"High",IF(AB756>=3,"Medium","Low")) -> High
A757: 6683-VLCTZ | B757: Male | C757: 1 | D757: No | E757: No | F757: 20 | G757: Yes | H757: Yes | I757: Fiber optic | J757: No | K757: No | L757: Yes | M757: No | N757: Yes | O757: Yes | P757: Month-to-month | Q757: Yes | R757: Electronic check | S757: 98.55 | T757: 1842.8 | U757: Yes | V757: =IF(ISNUMBER(T757),T757,0) -> 1842.8 | W757: =IF(U757="Yes",1,0) -> 1 | X757: =IF(F757<=12,"0-12 months",IF(F757<=24,"13-24 months",IF(F757<=48,"25-48 months","49-72 months"))) -> 13-24 months | Y757: =IF(C757=1,"Yes","No") -> Yes | Z757: =COUNTIF(J757:O757,"Yes") -> 3 | AA757: =S757*W757 -> 98.55 | AB757: =(P757="Month-to-month")+(I757="Fiber optic")+(R757="Electronic check")+(F757<=12)+(M757="No")+(J757="No") -> 5 | AC757: =IF(AB757>=5,"High",IF(AB757>=3,"Medium","Low")) -> High
A758: 5730-DBDSI | B758: Male | C758: 0 | D758: No | E758: No | F758: 66 | G758: Yes | H758: No | I758: No | J758: No internet service | K758: No internet service | L758: No internet service | M758: No internet service | N758: No internet service | O758: No internet service | P758: Two year | Q758: No | R758: Bank transfer (automatic) | S758: 19.7 | T758: 1253.8 | U758: No | V758: =IF(ISNUMBER(T758),T758,0) -> 1253.8 | W758: =IF(U758="Yes",1,0) -> 0 | X758: =IF(F758<=12,"0-12 months",IF(F758<=24,"13-24 months",IF(F758<=48,"25-48 months","49-72 months"))) -> 49-72 months | Y758: =IF(C758=1,"Yes","No") -> No | Z758: =COUNTIF(J758:O758,"Yes") -> 0 | AA758: =S758*W758 -> 0 | AB758: =(P758="Month-to-month")+(I758="Fiber optic")+(R758="Electronic check")+(F758<=12)+(M758="No")+(J758="No") -> 0 | AC758: =IF(AB758>=5,"High",IF(AB758>=3,"Medium","Low")) -> Low
A759: 0030-FNXPP | B759: Female | C759: 0 | D759: No | E759: No | F759: 3 | G759: Yes | H759: No | I759: No | J759: No internet service | K759: No internet service | L759: No internet service | M759: No internet service | N759: No internet service | O759: No internet service | P759: Month-to-month | Q759: No | R759: Mailed check | S759: 19.85 | T759: 57.2 | U759: No | V759: =IF(ISNUMBER(T759),T759,0) -> 57.2 | W759: =IF(U759="Yes",1,0) -> 0 | X759: =IF(F759<=12,"0-12 months",IF(F759<=24,"13-24 months",IF(F759<=48,"25-48 months","49-72 months"))) -> 0-12 months | Y759: =IF(C759=1,"Yes","No") -> No | Z759: =COUNTIF(J759:O759,"Yes") -> 0 | AA759: =S759*W759 -> 0 | AB759: =(P759="Month-to-month")+(I759="Fiber optic")+(R759="Electronic check")+(F759<=12)+(M759="No")+(J759="No") -> 2 | AC759: =IF(AB759>=5,"High",IF(AB759>=3,"Medium","Low")) -> Low
A760: 2189-WWOEW | B760: Female | C760: 0 | D760: No | E760: Yes | F760: 15 | G760: Yes | H760: No | I760: Fiber optic | J760: No | K760: Yes | L760: No | M760: No | N760: No | O760: Yes | P760: Month-to-month | Q760: Yes | R760: Bank transfer (automatic) | S760: 85.9 | T760: 1269.55 | U760: Yes | V760: =IF(ISNUMBER(T760),T760,0) -> 1269.55 | W760: =IF(U760="Yes",1,0) -> 1 | X760: =IF(F760<=12,"0-12 months",IF(F760<=24,"13-24 months",IF(F760<=48,"25-48 months","49-72 months"))) -> 13-24 months | Y760: =IF(C760=1,"Yes","No") -> No | Z760: =COUNTIF(J760:O760,"Yes") -> 2 | AA760: =S760*W760 -> 85.9 | AB760: =(P760="Month-to-month")+(I760="Fiber optic")+(R760="Electronic check")+(F760<=12)+(M760="No")+(J760="No") -> 4 | AC760: =IF(AB760>=5,"High",IF(AB760>=3,"Medium","Low")) -> Medium
A761: 5684-FJVYR | B761: Female | C761: 0 | D761: Yes | E761: Yes | F761: 72 | G761: Yes | H761: Yes | I761: Fiber optic | J761: Yes | K761: Yes | L761: No | M761: Yes | N761: No | O761: No | P761: Two year | Q761: Yes | R761: Bank transfer (automatic) | S761: 90.35 | T761: 6563.4 | U761: No | V761: =IF(ISNUMBER(T761),T761,0) -> 6563.4 | W761: =IF(U761="Yes",1,0) -> 0 | X761: =IF(F761<=12,"0-12 months",IF(F761<=24,"13-24 months",IF(F761<=48,"25-48 months","49-72 months"))) -> 49-72 months | Y761: =IF(C761=1,"Yes","No") -> No | Z761: =COUNTIF(J761:O761,"Yes") -> 3 | AA761: =S761*W761 -> 0 | AB761: =(P761="Month-to-month")+(I761="Fiber optic")+(R761="Electronic check")+(F761<=12)+(M761="No")+(J761="No") -> 1 | AC761: =IF(AB761>=5,"High",IF(AB761>=3,"Medium","Low")) -> Low
A762: 4013-GUXND | B762: Male | C762: 0 | D762: No | E762: No | F762: 1 | G762: Yes | H762: No | I762: No | J762: No internet service | K762: No internet service | L762: No internet service | M762: No internet service | N762: No internet service | O762: No internet service | P762: Month-to-month | Q762: No | R762: Mailed check | S762: 20.8 | T762: 20.8 | U762: No | V762: =IF(ISNUMBER(T762),T762,0) -> 20.8 | W762: =IF(U762="Yes",1,0) -> 0 | X762: =IF(F762<=12,"0-12 months",IF(F762<=24,"13-24 months",IF(F762<=48,"25-48 months","49-72 months"))) -> 0-12 months | Y762: =IF(C762=1,"Yes","No") -> No | Z762: =COUNTIF(J762:O762,"Yes") -> 0 | AA762: =S762*W762 -> 0 | AB762: =(P762="Month-to-month")+(I762="Fiber optic")+(R762="Electronic check")+(F762<=12)+(M762="No")+(J762="No") -> 2 | AC762: =IF(AB762>=5,"High",IF(AB762>=3,"Medium","Low")) -> Low
A763: 1894-IGFSG | B763: Female | C763: 0 | D763: No | E763: No | F763: 22 | G763: Yes | H763: No | I763: Fiber optic | J763: No | K763: No | L763: No | M763: No | N763: Yes | O763: Yes | P763: Month-to-month | Q763: No | R763: Electronic check | S763: 89.25 | T763: 1907.85 | U763: Yes | V763: =IF(ISNUMBER(T763),T763,0) -> 1907.85 | W763: =IF(U763="Yes",1,0) -> 1 | X763: =IF(F763<=12,"0-12 months",IF(F763<=24,"13-24 months",IF(F763<=48,"25-48 months","49-72 months"))) -> 13-24 months | Y763: =IF(C763=1,"Yes","No") -> No | Z763: =COUNTIF(J763:O763,"Yes") -> 2 | AA763: =S763*W763 -> 89.25 | AB763: =(P763="Month-to-month")+(I763="Fiber optic")+(R763="Electronic check")+(F763<=12)+(M763="No")+(J763="No") -> 5 | AC763: =IF(AB763>=5,"High",IF(AB763>=3,"Medium","Low")) -> High
A764: 7379-POKDZ | B764: Male | C764: 0 | D764: Yes | E764: No | F764: 3 | G764: Yes | H764: No | I764: Fiber optic | J764: No | K764: No | L764: No | M764: No | N764: No | O764: No | P764: Month-to-month | Q764: Yes | R764: Electronic check | S764: 70.3 | T764: 208.85 | U764: Yes | V764: =IF(ISNUMBER(T764),T764,0) -> 208.85 | W764: =IF(U764="Yes",1,0) -> 1 | X764: =IF(F764<=12,"0-12 months",IF(F764<=24,"13-24 months",IF(F764<=48,"25-48 months","49-72 months"))) -> 0-12 months | Y764: =IF(C764=1,"Yes","No") -> No | Z764: =COUNTIF(J764:O764,"Yes") -> 0 | AA764: =S764*W764 -> 70.3 | AB764: =(P764="Month-to-month")+(I764="Fiber optic")+(R764="Electronic check")+(F764<=12)+(M764="No")+(J764="No") -> 6 | AC764: =IF(AB764>=5,"High",IF(AB764>=3,"Medium","Low")) -> High
A765: 1266-NZYUI | B765: Female | C765: 0 | D765: Yes | E765: Yes | F765: 72 | G765: Yes | H765: Yes | I765: DSL | J765: Yes | K765: No | L765: Yes | M765: Yes | N765: No | O765: No | P765: Two year | Q765: No | R765: Bank transfer (automatic) | S765: 66.85 | T765: 4758.8 | U765: No | V765: =IF(ISNUMBER(T765),T765,0) -> 4758.8 | W765: =IF(U765="Yes",1,0) -> 0 | X765: =IF(F765<=12,"0-12 months",IF(F765<=24,"13-24 months",IF(F765<=48,"25-48 months","49-72 months"))) -> 49-72 months | Y765: =IF(C765=1,"Yes","No") -> No | Z765: =COUNTIF(J765:O765,"Yes") -> 3 | AA765: =S765*W765 -> 0 | AB765: =(P765="Month-to-month")+(I765="Fiber optic")+(R765="Electronic check")+(F765<=12)+(M765="No")+(J765="No") -> 0 | AC765: =IF(AB765>=5,"High",IF(AB765>=3,"Medium","Low")) -> Low
A766: 7969-FFOWG | B766: Male | C766: 0 | D766: Yes | E766: Yes | F766: 65 | G766: Yes | H766: No | I766: No | J766: No internet service | K766: No internet service | L766: No internet service | M766: No internet service | N766: No internet service | O766: No internet service | P766: Two year | Q766: No | R766: Mailed check | S766: 19.9 | T766: 1292.6 | U766: No | V766: =IF(ISNUMBER(T766),T766,0) -> 1292.6 | W766: =IF(U766="Yes",1,0) -> 0 | X766: =IF(F766<=12,"0-12 months",IF(F766<=24,"13-24 months",IF(F766<=48,"25-48 months","49-72 months"))) -> 49-72 months | Y766: =IF(C766=1,"Yes","No") -> No | Z766: =COUNTIF(J766:O766,"Yes") -> 0 | AA766: =S766*W766 -> 0 | AB766: =(P766="Month-to-month")+(I766="Fiber optic")+(R766="Electronic check")+(F766<=12)+(M766="No")+(J766="No") -> 0 | AC766: =IF(AB766>=5,"High",IF(AB766>=3,"Medium","Low")) -> Low
...

Sheet Analysis
A1: Churn drivers: what separates customers who leave from those who stay
A2: Every number is a live COUNTIFS / SUMIFS formula on the Data sheet. Lift = segment churn rate / overall churn rate.
A4: Overall | B4: Customers | C4: Churned | D4: Churn rate | E4: Monthly revenue (MRR) | F4: Lost MRR | G4: % of lost MRR | H4: Lift vs average
A5: All customers | B5: =COUNTA(Data!$A$2:$A$7044) -> 7043 | C5: =SUM(Data!$W$2:$W$7044) -> 1869 | D5: =IFERROR(C5/B5,0) -> 0.26536987 | E5: =SUM(Data!$S$2:$S$7044) -> 456116.6 | F5: =SUM(Data!$AA$2:$AA$7044) -> 139130.85 | G5: =IFERROR(F5/$F$5,0) -> 1 | H5: =IFERROR(D5/$D$5,0) -> 1
A7: Contract type
A8: Segment | B8: Customers | C8: Churned | D8: Churn rate | E8: Monthly revenue (MRR) | F8: Lost MRR | G8: % of lost MRR | H8: Lift vs average
A9: Month-to-month | B9: =COUNTIFS(Data!$P$2:$P$7044,A9) -> 3875 | C9: =COUNTIFS(Data!$P$2:$P$7044,A9,Data!$W$2:$W$7044,1) -> 1655 | D9: =IFERROR(C9/B9,0) -> 0.42709677 | E9: =SUMIFS(Data!$S$2:$S$7044,Data!$P$2:$P$7044,A9) -> 257294.15 | F9: =SUMIFS(Data!$AA$2:$AA$7044,Data!$P$2:$P$7044,A9) -> 120847.1 | G9: =IFERROR(F9/$F$5,0) -> 0.86858594 | H9: =IFERROR(D9/$D$5,0) -> 1.6094396
A10: One year | B10: =COUNTIFS(Data!$P$2:$P$7044,A10) -> 1473 | C10: =COUNTIFS(Data!$P$2:$P$7044,A10,Data!$W$2:$W$7044,1) -> 166 | D10: =IFERROR(C10/B10,0) -> 0.11269518 | E10: =SUMIFS(Data!$S$2:$S$7044,Data!$P$2:$P$7044,A10) -> 95816.6 | F10: =SUMIFS(Data!$AA$2:$AA$7044,Data!$P$2:$P$7044,A10) -> 14118.45 | G10: =IFERROR(F10/$F$5,0) -> 0.10147606 | H10: =IFERROR(D10/$D$5,0) -> 0.4246721
A11: Two year | B11: =COUNTIFS(Data!$P$2:$P$7044,A11) -> 1695 | C11: =COUNTIFS(Data!$P$2:$P$7044,A11,Data!$W$2:$W$7044,1) -> 48 | D11: =IFERROR(C11/B11,0) -> 0.028318584 | E11: =SUMIFS(Data!$S$2:$S$7044,Data!$P$2:$P$7044,A11) -> 103005.85 | F11: =SUMIFS(Data!$AA$2:$AA$7044,Data!$P$2:$P$7044,A11) -> 4165.3 | G11: =IFERROR(F11/$F$5,0) -> 0.029938004 | H11: =IFERROR(D11/$D$5,0) -> 0.10671364
A14: Tenure
A15: Segment | B15: Customers | C15: Churned | D15: Churn rate | E15: Monthly revenue (MRR) | F15: Lost MRR | G15: % of lost MRR | H15: Lift vs average
A16: 0-12 months | B16: =COUNTIFS(Data!$X$2:$X$7044,A16) -> 2186 | C16: =COUNTIFS(Data!$X$2:$X$7044,A16,Data!$W$2:$W$7044,1) -> 1037 | D16: =IFERROR(C16/B16,0) -> 0.47438243 | E16: =SUMIFS(Data!$S$2:$S$7044,Data!$X$2:$X$7044,A16) -> 122629.75 | F16: =SUMIFS(Data!$AA$2:$AA$7044,Data!$X$2:$X$7044,A16) -> 68954.25 | G16: =IFERROR(F16/$F$5,0) -> 0.49560719 | H16: =IFERROR(D16/$D$5,0) -> 1.7876273
A17: 13-24 months | B17: =COUNTIFS(Data!$X$2:$X$7044,A17) -> 1024 | C17: =COUNTIFS(Data!$X$2:$X$7044,A17,Data!$W$2:$W$7044,1) -> 294 | D17: =IFERROR(C17/B17,0) -> 0.28710938 | E17: =SUMIFS(Data!$S$2:$S$7044,Data!$X$2:$X$7044,A17) -> 62829.85 | F17: =SUMIFS(Data!$AA$2:$AA$7044,Data!$X$2:$X$7044,A17) -> 23081.65 | G17: =IFERROR(F17/$F$5,0) -> 0.16589886 | H17: =IFERROR(D17/$D$5,0) -> 1.0819215
A18: 25-48 months | B18: =COUNTIFS(Data!$X$2:$X$7044,A18) -> 1594 | C18: =COUNTIFS(Data!$X$2:$X$7044,A18,Data!$W$2:$W$7044,1) -> 325 | D18: =IFERROR(C18/B18,0) -> 0.20388959 | E18: =SUMIFS(Data!$S$2:$S$7044,Data!$X$2:$X$7044,A18) -> 105093.3 | F18: =SUMIFS(Data!$AA$2:$AA$7044,Data!$X$2:$X$7044,A18) -> 27462.5 | G18: =IFERROR(F18/$F$5,0) -> 0.19738613 | H18: =IFERROR(D18/$D$5,0) -> 0.76832229
A19: 49-72 months | B19: =COUNTIFS(Data!$X$2:$X$7044,A19) -> 2239 | C19: =COUNTIFS(Data!$X$2:$X$7044,A19,Data!$W$2:$W$7044,1) -> 213 | D19: =IFERROR(C19/B19,0) -> 0.095131755 | E19: =SUMIFS(Data!$S$2:$S$7044,Data!$X$2:$X$7044,A19) -> 165563.7 | F19: =SUMIFS(Data!$AA$2:$AA$7044,Data!$X$2:$X$7044,A19) -> 19632.45 | G19: =IFERROR(F19/$F$5,0) -> 0.14110781 | H19: =IFERROR(D19/$D$5,0) -> 0.3584874
A22: Internet service
A23: Segment | B23: Customers | C23: Churned | D23: Churn rate | E23: Monthly revenue (MRR) | F23: Lost MRR | G23: % of lost MRR | H23: Lift vs average
A24: Fiber optic | B24: =COUNTIFS(Data!$I$2:$I$7044,A24) -> 3096 | C24: =COUNTIFS(Data!$I$2:$I$7044,A24,Data!$W$2:$W$7044,1) -> 1297 | D24: =IFERROR(C24/B24,0) -> 0.41892765 | E24: =SUMIFS(Data!$S$2:$S$7044,Data!$I$2:$I$7044,A24) -> 283284.4 | F24: =SUMIFS(Data!$AA$2:$AA$7044,Data!$I$2:$I$7044,A24) -> 114300.05 | G24: =IFERROR(F24/$F$5,0) -> 0.82152916 | H24: =IFERROR(D24/$D$5,0) -> 1.5786557
A25: DSL | B25: =COUNTIFS(Data!$I$2:$I$7044,A25) -> 2421 | C25: =COUNTIFS(Data!$I$2:$I$7044,A25,Data!$W$2:$W$7044,1) -> 459 | D25: =IFERROR(C25/B25,0) -> 0.18959108 | E25: =SUMIFS(Data!$S$2:$S$7044,Data!$I$2:$I$7044,A25) -> 140665.35 | F25: =SUMIFS(Data!$AA$2:$AA$7044,Data!$I$2:$I$7044,A25) -> 22529.2 | G25: =IFERROR(F25/$F$5,0) -> 0.16192814 | H25: =IFERROR(D25/$D$5,0) -> 0.71444086
A26: No | B26: =COUNTIFS(Data!$I$2:$I$7044,A26) -> 1526 | C26: =COUNTIFS(Data!$I$2:$I$7044,A26,Data!$W$2:$W$7044,1) -> 113 | D26: =IFERROR(C26/B26,0) -> 0.074049803 | E26: =SUMIFS(Data!$S$2:$S$7044,Data!$I$2:$I$7044,A26) -> 32166.85 | F26: =SUMIFS(Data!$AA$2:$AA$7044,Data!$I$2:$I$7044,A26) -> 2301.6 | G26: =IFERROR(F26/$F$5,0) -> 0.016542701 | H26: =IFERROR(D26/$D$5,0) -> 0.27904375
A29: Payment method
A30: Segment | B30: Customers | C30: Churned | D30: Churn rate | E30: Monthly revenue (MRR) | F30: Lost MRR | G30: % of lost MRR | H30: Lift vs average
A31: Electronic check | B31: =COUNTIFS(Data!$R$2:$R$7044,A31) -> 2365 | C31: =COUNTIFS(Data!$R$2:$R$7044,A31,Data!$W$2:$W$7044,1) -> 1071 | D31: =IFERROR(C31/B31,0) -> 0.45285412 | E31: =SUMIFS(Data!$S$2:$S$7044,Data!$R$2:$R$7044,A31) -> 180345 | F31: =SUMIFS(Data!$AA$2:$AA$7044,Data!$R$2:$R$7044,A31) -> 84288.75 | G31: =IFERROR(F31/$F$5,0) -> 0.60582358 | H31: =IFERROR(D31/$D$5,0) -> 1.7065017
A32: Mailed check | B32: =COUNTIFS(Data!$R$2:$R$7044,A32) -> 1612 | C32: =COUNTIFS(Data!$R$2:$R$7044,A32,Data!$W$2:$W$7044,1) -> 308 | D32: =IFERROR(C32/B32,0) -> 0.191067 | E32: =SUMIFS(Data!$S$2:$S$7044,Data!$R$2:$R$7044,A32) -> 70794.3 | F32: =SUMIFS(Data!$AA$2:$AA$7044,Data!$R$2:$R$7044,A32) -> 16803.6 | G32: =IFERROR(F32/$F$5,0) -> 0.12077551 | H32: =IFERROR(D32/$D$5,0) -> 0.7200026
A33: Bank transfer (automatic) | B33: =COUNTIFS(Data!$R$2:$R$7044,A33) -> 1544 | C33: =COUNTIFS(Data!$R$2:$R$7044,A33,Data!$W$2:$W$7044,1) -> 258 | D33: =IFERROR(C33/B33,0) -> 0.16709845 | E33: =SUMIFS(Data!$S$2:$S$7044,Data!$R$2:$R$7044,A33) -> 103745.45 | F33: =SUMIFS(Data!$AA$2:$AA$7044,Data!$R$2:$R$7044,A33) -> 20091.9 | G33: =IFERROR(F33/$F$5,0) -> 0.1444101 | H33: =IFERROR(D33/$D$5,0) -> 0.6296813
A34: Credit card (automatic) | B34: =COUNTIFS(Data!$R$2:$R$7044,A34) -> 1522 | C34: =COUNTIFS(Data!$R$2:$R$7044,A34,Data!$W$2:$W$7044,1) -> 232 | D34: =IFERROR(C34/B34,0) -> 0.15243101 | E34: =SUMIFS(Data!$S$2:$S$7044,Data!$R$2:$R$7044,A34) -> 101231.85 | F34: =SUMIFS(Data!$AA$2:$AA$7044,Data!$R$2:$R$7044,A34) -> 17946.6 | G34: =IFERROR(F34/$F$5,0) -> 0.1289908 | H34: =IFERROR(D34/$D$5,0) -> 0.57440964
A37: Tech support
A38: Segment | B38: Customers | C38: Churned | D38: Churn rate | E38: Monthly revenue (MRR) | F38: Lost MRR | G38: % of lost MRR | H38: Lift vs average
A39: No | B39: =COUNTIFS(Data!$M$2:$M$7044,A39) -> 3473 | C39: =COUNTIFS(Data!$M$2:$M$7044,A39,Data!$W$2:$W$7044,1) -> 1446 | D39: =IFERROR(C39/B39,0) -> 0.41635474 | E39: =SUMIFS(Data!$S$2:$S$7044,Data!$M$2:$M$7044,A39) -> 259039.55 | F39: =SUMIFS(Data!$AA$2:$AA$7044,Data!$M$2:$M$7044,A39) -> 110709.8 | G39: =IFERROR(F39/$F$5,0) -> 0.79572431 | H39: =IFERROR(D39/$D$5,0) -> 1.5689601
A40: Yes | B40: =COUNTIFS(Data!$M$2:$M$7044,A40) -> 2044 | C40: =COUNTIFS(Data!$M$2:$M$7044,A40,Data!$W$2:$W$7044,1) -> 310 | D40: =IFERROR(C40/B40,0) -> 0.15166341 | E40: =SUMIFS(Data!$S$2:$S$7044,Data!$M$2:$M$7044,A40) -> 164910.2 | F40: =SUMIFS(Data!$AA$2:$AA$7044,Data!$M$2:$M$7044,A40) -> 26119.45 | G40: =IFERROR(F40/$F$5,0) -> 0.18773299 | H40: =IFERROR(D40/$D$5,0) -> 0.57151705
A41: No internet service | B41: =COUNTIFS(Data!$M$2:$M$7044,A41) -> 1526 | C41: =COUNTIFS(Data!$M$2:$M$7044,A41,Data!$W$2:$W$7044,1) -> 113 | D41: =IFERROR(C41/B41,0) -> 0.074049803 | E41: =SUMIFS(Data!$S$2:$S$7044,Data!$M$2:$M$7044,A41) -> 32166.85 | F41: =SUMIFS(Data!$AA$2:$AA$7044,Data!$M$2:$M$7044,A41) -> 2301.6 | G41: =IFERROR(F41/$F$5,0) -> 0.016542701 | H41: =IFERROR(D41/$D$5,0) -> 0.27904375
A44: Online security
A45: Segment | B45: Customers | C45: Churned | D45: Churn rate | E45: Monthly revenue (MRR) | F45: Lost MRR | G45: % of lost MRR | H45: Lift vs average
A46: No | B46: =COUNTIFS(Data!$J$2:$J$7044,A46) -> 3498 | C46: =COUNTIFS(Data!$J$2:$J$7044,A46,Data!$W$2:$W$7044,1) -> 1461 | D46: =IFERROR(C46/B46,0) -> 0.41766724 | E46: =SUMIFS(Data!$S$2:$S$7044,Data!$J$2:$J$7044,A46) -> 264774.35 | F46: =SUMIFS(Data!$AA$2:$AA$7044,Data!$J$2:$J$7044,A46) -> 112762.75 | G46: =IFERROR(F46/$F$5,0) -> 0.81047985 | H46: =IFERROR(D46/$D$5,0) -> 1.573906
A47: Yes | B47: =COUNTIFS(Data!$J$2:$J$7044,A47) -> 2019 | C47: =COUNTIFS(Data!$J$2:$J$7044,A47,Data!$W$2:$W$7044,1) -> 295 | D47: =IFERROR(C47/B47,0) -> 0.14611194 | E47: =SUMIFS(Data!$S$2:$S$7044,Data!$J$2:$J$7044,A47) -> 159175.4 | F47: =SUMIFS(Data!$AA$2:$AA$7044,Data!$J$2:$J$7044,A47) -> 24066.5 | G47: =IFERROR(F47/$F$5,0) -> 0.17297745 | H47: =IFERROR(D47/$D$5,0) -> 0.55059731
A48: No internet service | B48: =COUNTIFS(Data!$J$2:$J$7044,A48) -> 1526 | C48: =COUNTIFS(Data!$J$2:$J$7044,A48,Data!$W$2:$W$7044,1) -> 113 | D48: =IFERROR(C48/B48,0) -> 0.074049803 | E48: =SUMIFS(Data!$S$2:$S$7044,Data!$J$2:$J$7044,A48) -> 32166.85 | F48: =SUMIFS(Data!$AA$2:$AA$7044,Data!$J$2:$J$7044,A48) -> 2301.6 | G48: =IFERROR(F48/$F$5,0) -> 0.016542701 | H48: =IFERROR(D48/$D$5,0) -> 0.27904375
A51: Senior citizen
A52: Segment | B52: Customers | C52: Churned | D52: Churn rate | E52: Monthly revenue (MRR) | F52: Lost MRR | G52: % of lost MRR | H52: Lift vs average
A53: Yes | B53: =COUNTIFS(Data!$Y$2:$Y$7044,A53) -> 1142 | C53: =COUNTIFS(Data!$Y$2:$Y$7044,A53,Data!$W$2:$W$7044,1) -> 476 | D53: =IFERROR(C53/B53,0) -> 0.41681261 | E53: =SUMIFS(Data!$S$2:$S$7044,Data!$Y$2:$Y$7044,A53) -> 91154.85 | F53: =SUMIFS(Data!$AA$2:$AA$7044,Data!$Y$2:$Y$7044,A53) -> 38419.6 | G53: =IFERROR(F53/$F$5,0) -> 0.27614005 | H53: =IFERROR(D53/$D$5,0) -> 1.5706855
A54: No | B54: =COUNTIFS(Data!$Y$2:$Y$7044,A54) -> 5901 | C54: =COUNTIFS(Data!$Y$2:$Y$7044,A54,Data!$W$2:$W$7044,1) -> 1393 | D54: =IFERROR(C54/B54,0) -> 0.23606168 | E54: =SUMIFS(Data!$S$2:$S$7044,Data!$Y$2:$Y$7044,A54) -> 364961.75 | F54: =SUMIFS(Data!$AA$2:$AA$7044,Data!$Y$2:$Y$7044,A54) -> 100711.25 | G54: =IFERROR(F54/$F$5,0) -> 0.72385995 | H54: =IFERROR(D54/$D$5,0) -> 0.88955722
...

Sheet Stats_Tests
A1: Is each driver real or chance? Chi-square tests in Excel
A2: CHITEST compares observed counts with the counts expected if churn were unrelated to the segment. p < 0.05 means the difference is very unlikely to be chance. It shows association, not cause.
A4: Driver | B4: p-value | C4: Significant at 5%?
A5: Contract type | B5: =CHITEST(B18:C20,E18:F20) -> 5.8630383e-258 | C5: =IF(B5<0.05,"Yes","No") -> Yes
A6: Tenure | B6: =CHITEST(B26:C29,E26:F29) -> 2.9437704e-185 | C6: =IF(B6<0.05,"Yes","No") -> Yes
A7: Internet service | B7: =CHITEST(B35:C37,E35:F37) -> 9.5717882e-160 | C7: =IF(B7<0.05,"Yes","No") -> Yes
A8: Payment method | B8: =CHITEST(B43:C46,E43:F46) -> 3.6823547e-140 | C8: =IF(B8<0.05,"Yes","No") -> Yes
A9: Tech support | B9: =CHITEST(B52:C54,E52:F54) -> 1.443084e-180 | C9: =IF(B9<0.05,"Yes","No") -> Yes
A10: Online security | B10: =CHITEST(B60:C62,E60:F62) -> 2.6611496e-185 | C10: =IF(B10<0.05,"Yes","No") -> Yes
A11: Senior citizen | B11: =CHITEST(B68:C69,E68:F69) -> 9.4779035e-37 | C11: =IF(B11<0.05,"Yes","No") -> Yes
A12: Paperless billing | B12: =CHITEST(B75:C76,E75:F76) -> 2.6145974e-58 | C12: =IF(B12<0.05,"Yes","No") -> Yes
A16: Contract type
A17: Segment | B17: Churned (observed) | C17: Stayed (observed) | D17: Row total | E17: Churned (expected) | F17: Stayed (expected)
A18: =Analysis!A9 -> Month-to-month | B18: =Analysis!C9 -> 1655 | C18: =Analysis!B9-Analysis!C9 -> 2220 | D18: =B18+C18 -> 3875 | E18: =D18*B$21/D$21 -> 1028.3082 | F18: =D18*C$21/D$21 -> 2846.6918
A19: =Analysis!A10 -> One year | B19: =Analysis!C10 -> 166 | C19: =Analysis!B10-Analysis!C10 -> 1307 | D19: =B19+C19 -> 1473 | E19: =D19*B$21/D$21 -> 390.88982 | F19: =D19*C$21/D$21 -> 1082.1102
A20: =Analysis!A11 -> Two year | B20: =Analysis!C11 -> 48 | C20: =Analysis!B11-Analysis!C11 -> 1647 | D20: =B20+C20 -> 1695 | E20: =D20*B$21/D$21 -> 449.80193 | F20: =D20*C$21/D$21 -> 1245.1981
A21: Total | B21: =SUM(B18:B20) -> 1869 | C21: =SUM(C18:C20) -> 5174 | D21: =SUM(D18:D20) -> 7043
A24: Tenure
A25: Segment | B25: Churned (observed) | C25: Stayed (observed) | D25: Row total | E25: Churned (expected) | F25: Stayed (expected)
A26: =Analysis!A16 -> 0-12 months | B26: =Analysis!C16 -> 1037 | C26: =Analysis!B16-Analysis!C16 -> 1149 | D26: =B26+C26 -> 2186 | E26: =D26*B$30/D$30 -> 580.09854 | F26: =D26*C$30/D$30 -> 1605.9015
A27: =Analysis!A17 -> 13-24 months | B27: =Analysis!C17 -> 294 | C27: =Analysis!B17-Analysis!C17 -> 730 | D27: =B27+C27 -> 1024 | E27: =D27*B$30/D$30 -> 271.73875 | F27: =D27*C$30/D$30 -> 752.26125
A28: =Analysis!A18 -> 25-48 months | B28: =Analysis!C18 -> 325 | C28: =Analysis!B18-Analysis!C18 -> 1269 | D28: =B28+C28 -> 1594 | E28: =D28*B$30/D$30 -> 422.99957 | F28: =D28*C$30/D$30 -> 1171.0004
A29: =Analysis!A19 -> 49-72 months | B29: =Analysis!C19 -> 213 | C29: =Analysis!B19-Analysis!C19 -> 2026 | D29: =B29+C29 -> 2239 | E29: =D29*B$30/D$30 -> 594.16314 | F29: =D29*C$30/D$30 -> 1644.8369
A30: Total | B30: =SUM(B26:B29) -> 1869 | C30: =SUM(C26:C29) -> 5174 | D30: =SUM(D26:D29) -> 7043
A33: Internet service
A34: Segment | B34: Churned (observed) | C34: Stayed (observed) | D34: Row total | E34: Churned (expected) | F34: Stayed (expected)
A35: =Analysis!A24 -> Fiber optic | B35: =Analysis!C24 -> 1297 | C35: =Analysis!B24-Analysis!C24 -> 1799 | D35: =B35+C35 -> 3096 | E35: =D35*B$38/D$38 -> 821.58512 | F35: =D35*C$38/D$38 -> 2274.4149
A36: =Analysis!A25 -> DSL | B36: =Analysis!C25 -> 459 | C36: =Analysis!B25-Analysis!C25 -> 1962 | D36: =B36+C36 -> 2421 | E36: =D36*B$38/D$38 -> 642.46046 | F36: =D36*C$38/D$38 -> 1778.5395
A37: =Analysis!A26 -> No | B37: =Analysis!C26 -> 113 | C37: =Analysis!B26-Analysis!C26 -> 1413 | D37: =B37+C37 -> 1526 | E37: =D37*B$38/D$38 -> 404.95442 | F37: =D37*C$38/D$38 -> 1121.0456
A38: Total | B38: =SUM(B35:B37) -> 1869 | C38: =SUM(C35:C37) -> 5174 | D38: =SUM(D35:D37) -> 7043
A41: Payment method
A42: Segment | B42: Churned (observed) | C42: Stayed (observed) | D42: Row total | E42: Churned (expected) | F42: Stayed (expected)
A43: =Analysis!A31 -> Electronic check | B43: =Analysis!C31 -> 1071 | C43: =Analysis!B31-Analysis!C31 -> 1294 | D43: =B43+C43 -> 2365 | E43: =D43*B$47/D$47 -> 627.59974 | F43: =D43*C$47/D$47 -> 1737.4003
A44: =Analysis!A32 -> Mailed check | B44: =Analysis!C32 -> 308 | C44: =Analysis!B32-Analysis!C32 -> 1304 | D44: =B44+C44 -> 1612 | E44: =D44*B$47/D$47 -> 427.77623 | F44: =D44*C$47/D$47 -> 1184.2238
A45: =Analysis!A33 -> Bank transfer (automatic) | B45: =Analysis!C33 -> 258 | C45: =Analysis!B33-Analysis!C33 -> 1286 | D45: =B45+C45 -> 1544 | E45: =D45*B$47/D$47 -> 409.73108 | F45: =D45*C$47/D$47 -> 1134.2689
A46: =Analysis!A34 -> Credit card (automatic) | B46: =Analysis!C34 -> 232 | C46: =Analysis!B34-Analysis!C34 -> 1290 | D46: =B46+C46 -> 1522 | E46: =D46*B$47/D$47 -> 403.89294 | F46: =D46*C$47/D$47 -> 1118.1071
A47: Total | B47: =SUM(B43:B46) -> 1869 | C47: =SUM(C43:C46) -> 5174 | D47: =SUM(D43:D46) -> 7043
A50: Tech support
A51: Segment | B51: Churned (observed) | C51: Stayed (observed) | D51: Row total | E51: Churned (expected) | F51: Stayed (expected)
A52: =Analysis!A39 -> No | B52: =Analysis!C39 -> 1446 | C52: =Analysis!B39-Analysis!C39 -> 2027 | D52: =B52+C52 -> 3473 | E52: =D52*B$55/D$55 -> 921.62956 | F52: =D52*C$55/D$55 -> 2551.3704
...

Sheet Risk_Segments
A1: Highest-risk customer profiles (contract x internet x payment)
A2: Ranked by churn rate among combinations with at least 100 customers (smaller groups are too noisy to rank).
A4: Contract | B4: Internet service | C4: Payment method | D4: Customers | E4: Churn rate | F4: Lost MRR | G4: Rate if ranked | H4: Rank | I4: Minimum customers to rank | J4: 100
A5: Month-to-month | B5: Fiber optic | C5: Electronic check | D5: =COUNTIFS(Data!$P$2:$P$7044,A5,Data!$I$2:$I$7044,B5,Data!$R$2:$R$7044,C5) -> 1307 | E5: =IFERROR(COUNTIFS(Data!$P$2:$P$7044,A5,Data!$I$2:$I$7044,B5,Data!$R$2:$R$7044,C5,Data!$W$2:$W$7044,1)/D5,0) -> 0.60367253 | F5: =SUMIFS(Data!$AA$2:$AA$7044,Data!$P$2:$P$7044,A5,Data!$I$2:$I$7044,B5,Data!$R$2:$R$7044,C5) -> 68281.5 | G5: =IF(D5>=$J$4,E5,"") -> 0.60367253 | H5: =IF(G5="","",RANK(G5,$G$5:$G$40)) -> 1
A6: Month-to-month | B6: Fiber optic | C6: Mailed check | D6: =COUNTIFS(Data!$P$2:$P$7044,A6,Data!$I$2:$I$7044,B6,Data!$R$2:$R$7044,C6) -> 201 | E6: =IFERROR(COUNTIFS(Data!$P$2:$P$7044,A6,Data!$I$2:$I$7044,B6,Data!$R$2:$R$7044,C6,Data!$W$2:$W$7044,1)/D6,0) -> 0.50746269 | F6: =SUMIFS(Data!$AA$2:$AA$7044,Data!$P$2:$P$7044,A6,Data!$I$2:$I$7044,B6,Data!$R$2:$R$7044,C6) -> 8407.25 | G6: =IF(D6>=$J$4,E6,"") -> 0.50746269 | H6: =IF(G6="","",RANK(G6,$G$5:$G$40)) -> 2
A7: Month-to-month | B7: Fiber optic | C7: Bank transfer (automatic) | D7: =COUNTIFS(Data!$P$2:$P$7044,A7,Data!$I$2:$I$7044,B7,Data!$R$2:$R$7044,C7) -> 327 | E7: =IFERROR(COUNTIFS(Data!$P$2:$P$7044,A7,Data!$I$2:$I$7044,B7,Data!$R$2:$R$7044,C7,Data!$W$2:$W$7044,1)/D7,0) -> 0.45565749 | F7: =SUMIFS(Data!$AA$2:$AA$7044,Data!$P$2:$P$7044,A7,Data!$I$2:$I$7044,B7,Data!$R$2:$R$7044,C7) -> 13062.1 | G7: =IF(D7>=$J$4,E7,"") -> 0.45565749 | H7: =IF(G7="","",RANK(G7,$G$5:$G$40)) -> 3
A8: Month-to-month | B8: Fiber optic | C8: Credit card (automatic) | D8: =COUNTIFS(Data!$P$2:$P$7044,A8,Data!$I$2:$I$7044,B8,Data!$R$2:$R$7044,C8) -> 293 | E8: =IFERROR(COUNTIFS(Data!$P$2:$P$7044,A8,Data!$I$2:$I$7044,B8,Data!$R$2:$R$7044,C8,Data!$W$2:$W$7044,1)/D8,0) -> 0.41638225 | F8: =SUMIFS(Data!$AA$2:$AA$7044,Data!$P$2:$P$7044,A8,Data!$I$2:$I$7044,B8,Data!$R$2:$R$7044,C8) -> 10731.15 | G8: =IF(D8>=$J$4,E8,"") -> 0.41638225 | H8: =IF(G8="","",RANK(G8,$G$5:$G$40)) -> 4
A9: Month-to-month | B9: DSL | C9: Electronic check | D9: =COUNTIFS(Data!$P$2:$P$7044,A9,Data!$I$2:$I$7044,B9,Data!$R$2:$R$7044,C9) -> 474 | E9: =IFERROR(COUNTIFS(Data!$P$2:$P$7044,A9,Data!$I$2:$I$7044,B9,Data!$R$2:$R$7044,C9,Data!$W$2:$W$7044,1)/D9,0) -> 0.40506329 | F9: =SUMIFS(Data!$AA$2:$AA$7044,Data!$P$2:$P$7044,A9,Data!$I$2:$I$7044,B9,Data!$R$2:$R$7044,C9) -> 8776.45 | G9: =IF(D9>=$J$4,E9,"") -> 0.40506329 | H9: =IF(G9="","",RANK(G9,$G$5:$G$40)) -> 5
A10: Month-to-month | B10: DSL | C10: Mailed check | D10: =COUNTIFS(Data!$P$2:$P$7044,A10,Data!$I$2:$I$7044,B10,Data!$R$2:$R$7044,C10) -> 367 | E10: =IFERROR(COUNTIFS(Data!$P$2:$P$7044,A10,Data!$I$2:$I$7044,B10,Data!$R$2:$R$7044,C10,Data!$W$2:$W$7044,1)/D10,0) -> 0.30790191 | F10: =SUMIFS(Data!$AA$2:$AA$7044,Data!$P$2:$P$7044,A10,Data!$I$2:$I$7044,B10,Data!$R$2:$R$7044,C10) -> 5292.1 | G10: =IF(D10>=$J$4,E10,"") -> 0.30790191 | H10: =IF(G10="","",RANK(G10,$G$5:$G$40)) -> 6
A11: Month-to-month | B11: DSL | C11: Credit card (automatic) | D11: =COUNTIFS(Data!$P$2:$P$7044,A11,Data!$I$2:$I$7044,B11,Data!$R$2:$R$7044,C11) -> 185 | E11: =IFERROR(COUNTIFS(Data!$P$2:$P$7044,A11,Data!$I$2:$I$7044,B11,Data!$R$2:$R$7044,C11,Data!$W$2:$W$7044,1)/D11,0) -> 0.27027027 | F11: =SUMIFS(Data!$AA$2:$AA$7044,Data!$P$2:$P$7044,A11,Data!$I$2:$I$7044,B11,Data!$R$2:$R$7044,C11) -> 2474.8 | G11: =IF(D11>=$J$4,E11,"") -> 0.27027027 | H11: =IF(G11="","",RANK(G11,$G$5:$G$40)) -> 7
A12: One year | B12: Fiber optic | C12: Electronic check | D12: =COUNTIFS(Data!$P$2:$P$7044,A12,Data!$I$2:$I$7044,B12,Data!$R$2:$R$7044,C12) -> 196 | E12: =IFERROR(COUNTIFS(Data!$P$2:$P$7044,A12,Data!$I$2:$I$7044,B12,Data!$R$2:$R$7044,C12,Data!$W$2:$W$7044,1)/D12,0) -> 0.26020408 | F12: =SUMIFS(Data!$AA$2:$AA$7044,Data!$P$2:$P$7044,A12,Data!$I$2:$I$7044,B12,Data!$R$2:$R$7044,C12) -> 5149.65 | G12: =IF(D12>=$J$4,E12,"") -> 0.26020408 | H12: =IF(G12="","",RANK(G12,$G$5:$G$40)) -> 8
A13: Month-to-month | B13: No | C13: Mailed check | D13: =COUNTIFS(Data!$P$2:$P$7044,A13,Data!$I$2:$I$7044,B13,Data!$R$2:$R$7044,C13) -> 325 | E13: =IFERROR(COUNTIFS(Data!$P$2:$P$7044,A13,Data!$I$2:$I$7044,B13,Data!$R$2:$R$7044,C13,Data!$W$2:$W$7044,1)/D13,0) -> 0.20615385 | F13: =SUMIFS(Data!$AA$2:$AA$7044,Data!$P$2:$P$7044,A13,Data!$I$2:$I$7044,B13,Data!$R$2:$R$7044,C13) -> 1345.05 | G13: =IF(D13>=$J$4,E13,"") -> 0.20615385 | H13: =IF(G13="","",RANK(G13,$G$5:$G$40)) -> 9
A14: Month-to-month | B14: DSL | C14: Bank transfer (automatic) | D14: =COUNTIFS(Data!$P$2:$P$7044,A14,Data!$I$2:$I$7044,B14,Data!$R$2:$R$7044,C14) -> 197 | E14: =IFERROR(COUNTIFS(Data!$P$2:$P$7044,A14,Data!$I$2:$I$7044,B14,Data!$R$2:$R$7044,C14,Data!$W$2:$W$7044,1)/D14,0) -> 0.19796954 | F14: =SUMIFS(Data!$AA$2:$AA$7044,Data!$P$2:$P$7044,A14,Data!$I$2:$I$7044,B14,Data!$R$2:$R$7044,C14) -> 1823.9 | G14: =IF(D14>=$J$4,E14,"") -> 0.19796954 | H14: =IF(G14="","",RANK(G14,$G$5:$G$40)) -> 10
A15: One year | B15: Fiber optic | C15: Credit card (automatic) | D15: =COUNTIFS(Data!$P$2:$P$7044,A15,Data!$I$2:$I$7044,B15,Data!$R$2:$R$7044,C15) -> 150 | E15: =IFERROR(COUNTIFS(Data!$P$2:$P$7044,A15,Data!$I$2:$I$7044,B15,Data!$R$2:$R$7044,C15,Data!$W$2:$W$7044,1)/D15,0) -> 0.15333333 | F15: =SUMIFS(Data!$AA$2:$AA$7044,Data!$P$2:$P$7044,A15,Data!$I$2:$I$7044,B15,Data!$R$2:$R$7044,C15) -> 2392.35 | G15: =IF(D15>=$J$4,E15,"") -> 0.15333333 | H15: =IF(G15="","",RANK(G15,$G$5:$G$40)) -> 11
A16: One year | B16: Fiber optic | C16: Bank transfer (automatic) | D16: =COUNTIFS(Data!$P$2:$P$7044,A16,Data!$I$2:$I$7044,B16,Data!$R$2:$R$7044,C16) -> 157 | E16: =IFERROR(COUNTIFS(Data!$P$2:$P$7044,A16,Data!$I$2:$I$7044,B16,Data!$R$2:$R$7044,C16,Data!$W$2:$W$7044,1)/D16,0) -> 0.14649682 | F16: =SUMIFS(Data!$AA$2:$AA$7044,Data!$P$2:$P$7044,A16,Data!$I$2:$I$7044,B16,Data!$R$2:$R$7044,C16) -> 2344.35 | G16: =IF(D16>=$J$4,E16,"") -> 0.14649682 | H16: =IF(G16="","",RANK(G16,$G$5:$G$40)) -> 12
... A40: Two year | B40: No | C40: Electronic check | D40: =COUNTIFS(Data!$P$2:$P$7044,A40,Data!$I$2:$I$7044,B40,Data!$R$2:$R$7044,C40) -> 18 | E40: =IFERROR(COUNTIFS(Data!$P$2:$P$7044,A40,Data!$I$2:$I$7044,B40,Data!$R$2:$R$7044,C40,Data!$W$2:$W$7044,1)/D40,0) -> 0 | F40: =SUMIFS(Data!$AA$2:$AA$7044,Data!$P$2:$P$7044,A40,Data!$I$2:$I$7044,B40,Data!$R$2:$R$7044,C40) -> 0 | G40: =IF(D40>=$J$4,E40,"") | H40: =IF(G40="","",RANK(G40,$G$5:$G$40))

Sheet At_Risk
A1: Who to save: the risk score and the active customers it flags
A2: Risk score = 1 point each for month-to-month, fiber optic, electronic check, tenure <= 12 months, no tech support, no online security. The churn rate column checks that a higher score really means more churn.
A4: Risk score | B4: All customers | C4: Churned | D4: Churn rate | E4: Active customers | F4: Active customers' MRR | G4: Risk level
